<<< PROJECT PART I
<<< -- process set (n=3) with 1 CPU-bound process
<<< -- seed=32; lambda=0.001000; bound=1024
CPU-bound process A0: arrival time 319ms; 25 CPU bursts
I/O-bound process A1: arrival time 506ms; 5 CPU bursts
I/O-bound process A2: arrival time 821ms; 15 CPU bursts

<<< PROJECT PART II
<<< -- t_cs=4ms; alpha=0.75; t_slice=256ms
time 0ms: Simulator started for FCFS [Q empty]
time 319ms: Process A0 arrived; added to ready queue [Q A0]
time 321ms: Process A0 started using the CPU for 1448ms burst [Q empty]
time 506ms: Process A1 arrived; added to ready queue [Q A1]
time 821ms: Process A2 arrived; added to ready queue [Q A1 A2]
time 1769ms: Process A0 completed a CPU burst; 24 bursts to go [Q A1 A2]
time 1769ms: Process A0 switching out of CPU; blocking on I/O until time 2379ms [Q A1 A2]
time 1773ms: Process A1 started using the CPU for 971ms burst [Q A2]
time 2379ms: Process A0 completed I/O; added to ready queue [Q A2 A0]
time 2744ms: Process A1 completed a CPU burst; 4 bursts to go [Q A2 A0]
time 2744ms: Process A1 switching out of CPU; blocking on I/O until time 3178ms [Q A2 A0]
time 2748ms: Process A2 started using the CPU for 408ms burst [Q A0]
time 3156ms: Process A2 completed a CPU burst; 14 bursts to go [Q A0]
time 3156ms: Process A2 switching out of CPU; blocking on I/O until time 8670ms [Q A0]
time 3160ms: Process A0 started using the CPU for 316ms burst [Q empty]
time 3178ms: Process A1 completed I/O; added to ready queue [Q A1]
time 3476ms: Process A0 completed a CPU burst; 23 bursts to go [Q A1]
time 3476ms: Process A0 switching out of CPU; blocking on I/O until time 3952ms [Q A1]
time 3480ms: Process A1 started using the CPU for 129ms burst [Q empty]
time 3609ms: Process A1 completed a CPU burst; 3 bursts to go [Q empty]
time 3609ms: Process A1 switching out of CPU; blocking on I/O until time 4875ms [Q empty]
time 3952ms: Process A0 completed I/O; added to ready queue [Q A0]
time 3954ms: Process A0 started using the CPU for 3556ms burst [Q empty]
time 4875ms: Process A1 completed I/O; added to ready queue [Q A1]
time 7510ms: Process A0 completed a CPU burst; 22 bursts to go [Q A1]
time 7510ms: Process A0 switching out of CPU; blocking on I/O until time 8476ms [Q A1]
time 7514ms: Process A1 started using the CPU for 188ms burst [Q empty]
time 7702ms: Process A1 completed a CPU burst; 2 bursts to go [Q empty]
time 7702ms: Process A1 switching out of CPU; blocking on I/O until time 9200ms [Q empty]
time 8476ms: Process A0 completed I/O; added to ready queue [Q A0]
time 8478ms: Process A0 started using the CPU for 2516ms burst [Q empty]
time 8670ms: Process A2 completed I/O; added to ready queue [Q A2]
time 9200ms: Process A1 completed I/O; added to ready queue [Q A2 A1]
time 12891ms: Process A1 terminated [Q empty]
time 52148ms: Process A0 terminated [Q empty]
time 66002ms: Process A2 terminated [Q empty]
time 66004ms: Simulator ended for FCFS [Q empty]

time 0ms: Simulator started for SJF [Q empty]
time 319ms: Process A0 (tau 1000ms) arrived; added to ready queue [Q A0]
time 321ms: Process A0 (tau 1000ms) started using the CPU for 1448ms burst [Q empty]
time 506ms: Process A1 (tau 1000ms) arrived; added to ready queue [Q A1]
time 821ms: Process A2 (tau 1000ms) arrived; added to ready queue [Q A1 A2]
time 1769ms: Process A0 (tau 1000ms) completed a CPU burst; 24 bursts to go [Q A1 A2]
time 1769ms: Recalculated tau for process A0: old tau 1000ms ==> new tau 1336ms [Q A1 A2]
time 1769ms: Process A0 switching out of CPU; blocking on I/O until time 2379ms [Q A1 A2]
time 1773ms: Process A1 (tau 1000ms) started using the CPU for 971ms burst [Q A2]
time 2379ms: Process A0 (tau 1336ms) completed I/O; added to ready queue [Q A2 A0]
time 2744ms: Process A1 (tau 1000ms) completed a CPU burst; 4 bursts to go [Q A2 A0]
time 2744ms: Recalculated tau for process A1: old tau 1000ms ==> new tau 979ms [Q A2 A0]
time 2744ms: Process A1 switching out of CPU; blocking on I/O until time 3178ms [Q A2 A0]
time 2748ms: Process A2 (tau 1000ms) started using the CPU for 408ms burst [Q A0]
time 3156ms: Process A2 (tau 1000ms) completed a CPU burst; 14 bursts to go [Q A0]
time 3156ms: Recalculated tau for process A2: old tau 1000ms ==> new tau 556ms [Q A0]
time 3156ms: Process A2 switching out of CPU; blocking on I/O until time 8670ms [Q A0]
time 3160ms: Process A0 (tau 1336ms) started using the CPU for 316ms burst [Q empty]
time 3178ms: Process A1 (tau 979ms) completed I/O; added to ready queue [Q A1]
time 3476ms: Process A0 (tau 1336ms) completed a CPU burst; 23 bursts to go [Q A1]
time 3476ms: Recalculated tau for process A0: old tau 1336ms ==> new tau 571ms [Q A1]
time 3476ms: Process A0 switching out of CPU; blocking on I/O until time 3952ms [Q A1]
time 3480ms: Process A1 (tau 979ms) started using the CPU for 129ms burst [Q empty]
time 3609ms: Process A1 (tau 979ms) completed a CPU burst; 3 bursts to go [Q empty]
time 3609ms: Recalculated tau for process A1: old tau 979ms ==> new tau 342ms [Q empty]
time 3609ms: Process A1 switching out of CPU; blocking on I/O until time 4875ms [Q empty]
time 3952ms: Process A0 (tau 571ms) completed I/O; added to ready queue [Q A0]
time 3954ms: Process A0 (tau 571ms) started using the CPU for 3556ms burst [Q empty]
time 4875ms: Process A1 (tau 342ms) completed I/O; added to ready queue [Q A1]
time 7510ms: Process A0 (tau 571ms) completed a CPU burst; 22 bursts to go [Q A1]
time 7510ms: Recalculated tau for process A0: old tau 571ms ==> new tau 2810ms [Q A1]
time 7510ms: Process A0 switching out of CPU; blocking on I/O until time 8476ms [Q A1]
time 7514ms: Process A1 (tau 342ms) started using the CPU for 188ms burst [Q empty]
time 7702ms: Process A1 (tau 342ms) completed a CPU burst; 2 bursts to go [Q empty]
time 7702ms: Recalculated tau for process A1: old tau 342ms ==> new tau 227ms [Q empty]
time 7702ms: Process A1 switching out of CPU; blocking on I/O until time 9200ms [Q empty]
time 8476ms: Process A0 (tau 2810ms) completed I/O; added to ready queue [Q A0]
time 8478ms: Process A0 (tau 2810ms) started using the CPU for 2516ms burst [Q empty]
time 8670ms: Process A2 (tau 556ms) completed I/O; added to ready queue [Q A2]
time 9200ms: Process A1 (tau 227ms) completed I/O; added to ready queue [Q A1 A2]
time 10994ms: Process A0 (tau 2810ms) completed a CPU burst; 21 bursts to go [Q A1 A2]
time 10994ms: Recalculated tau for process A0: old tau 2810ms ==> new tau 2590ms [Q A1 A2]
time 10994ms: Process A0 switching out of CPU; blocking on I/O until time 11010ms [Q A1 A2]
time 10998ms: Process A1 (tau 227ms) started using the CPU for 302ms burst [Q A2]
time 11010ms: Process A0 (tau 2590ms) completed I/O; added to ready queue [Q A0 A2]
time 11300ms: Process A1 (tau 227ms) completed a CPU burst; 1 bursts to go [Q A0 A2]
time 11300ms: Recalculated tau for process A1: old tau 227ms ==> new tau 284ms [Q A0 A2]
time 11300ms: Process A1 switching out of CPU; blocking on I/O until time 12630ms [Q A0 A2]
time 11304ms: Process A0 (tau 2590ms) started using the CPU for 732ms burst [Q A2]
time 12036ms: Process A0 (tau 2590ms) completed a CPU burst; 20 bursts to go [Q A2]
time 12036ms: Recalculated tau for process A0: old tau 2590ms ==> new tau 1197ms [Q A2]
time 12036ms: Process A0 switching out of CPU; blocking on I/O until time 12707ms [Q A2]
time 12040ms: Process A2 (tau 556ms) started using the CPU for 182ms burst [Q empty]
time 12222ms: Process A2 (tau 556ms) completed a CPU burst; 13 bursts to go [Q empty]
time 12222ms: Recalculated tau for process A2: old tau 556ms ==> new tau 276ms [Q empty]
time 12222ms: Process A2 switching out of CPU; blocking on I/O until time 15968ms [Q empty]
time 12630ms: Process A1 (tau 284ms) completed I/O; added to ready queue [Q A1]
time 12632ms: Process A1 (tau 284ms) started using the CPU for 73ms burst [Q empty]
time 12705ms: Process A1 terminated [Q empty]
time 12707ms: Process A0 (tau 1197ms) completed I/O; added to ready queue [Q A0]
time 12709ms: Process A0 (tau 1197ms) started using the CPU for 1872ms burst [Q empty]
time 14581ms: Process A0 (tau 1197ms) completed a CPU burst; 19 bursts to go [Q empty]
time 14581ms: Recalculated tau for process A0: old tau 1197ms ==> new tau 1704ms [Q empty]
time 14581ms: Process A0 switching out of CPU; blocking on I/O until time 14665ms [Q empty]
time 14665ms: Process A0 (tau 1704ms) completed I/O; added to ready queue [Q A0]
time 14667ms: Process A0 (tau 1704ms) started using the CPU for 1020ms burst [Q empty]
time 15687ms: Process A0 (tau 1704ms) completed a CPU burst; 18 bursts to go [Q empty]
time 15687ms: Recalculated tau for process A0: old tau 1704ms ==> new tau 1191ms [Q empty]
time 15687ms: Process A0 switching out of CPU; blocking on I/O until time 16175ms [Q empty]
time 15968ms: Process A2 (tau 276ms) completed I/O; added to ready queue [Q A2]
time 15970ms: Process A2 (tau 276ms) started using the CPU for 89ms burst [Q empty]
time 16059ms: Process A2 (tau 276ms) completed a CPU burst; 12 bursts to go [Q empty]
time 16059ms: Recalculated tau for process A2: old tau 276ms ==> new tau 136ms [Q empty]
time 16059ms: Process A2 switching out of CPU; blocking on I/O until time 16069ms [Q empty]
time 16069ms: Process A2 (tau 136ms) completed I/O; added to ready queue [Q A2]
time 16071ms: Process A2 (tau 136ms) started using the CPU for 781ms burst [Q empty]
time 16175ms: Process A0 (tau 1191ms) completed I/O; added to ready queue [Q A0]
time 16852ms: Process A2 (tau 136ms) completed a CPU burst; 11 bursts to go [Q A0]
time 16852ms: Recalculated tau for process A2: old tau 136ms ==> new tau 620ms [Q A0]
time 16852ms: Process A2 switching out of CPU; blocking on I/O until time 17110ms [Q A0]
time 16856ms: Process A0 (tau 1191ms) started using the CPU for 228ms burst [Q empty]
time 17084ms: Process A0 (tau 1191ms) completed a CPU burst; 17 bursts to go [Q empty]
time 17084ms: Recalculated tau for process A0: old tau 1191ms ==> new tau 469ms [Q empty]
time 17084ms: Process A0 switching out of CPU; blocking on I/O until time 17433ms [Q empty]
time 17110ms: Process A2 (tau 620ms) completed I/O; added to ready queue [Q A2]
time 17112ms: Process A2 (tau 620ms) started using the CPU for 107ms burst [Q empty]
time 17219ms: Process A2 (tau 620ms) completed a CPU burst; 10 bursts to go [Q empty]
time 17219ms: Recalculated tau for process A2: old tau 620ms ==> new tau 236ms [Q empty]
time 17219ms: Process A2 switching out of CPU; blocking on I/O until time 17877ms [Q empty]
time 17433ms: Process A0 (tau 469ms) completed I/O; added to ready queue [Q A0]
time 17435ms: Process A0 (tau 469ms) started using the CPU for 2092ms burst [Q empty]
time 17877ms: Process A2 (tau 236ms) completed I/O; added to ready queue [Q A2]
time 19527ms: Process A0 (tau 469ms) completed a CPU burst; 16 bursts to go [Q A2]
time 19527ms: Recalculated tau for process A0: old tau 469ms ==> new tau 1687ms [Q A2]
time 19527ms: Process A0 switching out of CPU; blocking on I/O until time 19751ms [Q A2]
time 19531ms: Process A2 (tau 236ms) started using the CPU for 65ms burst [Q empty]
time 19596ms: Process A2 (tau 236ms) completed a CPU burst; 9 bursts to go [Q empty]
time 19596ms: Recalculated tau for process A2: old tau 236ms ==> new tau 108ms [Q empty]
time 19596ms: Process A2 switching out of CPU; blocking on I/O until time 25470ms [Q empty]
time 19751ms: Process A0 (tau 1687ms) completed I/O; added to ready queue [Q A0]
time 19753ms: Process A0 (tau 1687ms) started using the CPU for 3380ms burst [Q empty]
time 23133ms: Process A0 (tau 1687ms) completed a CPU burst; 15 bursts to go [Q empty]
time 23133ms: Recalculated tau for process A0: old tau 1687ms ==> new tau 2957ms [Q empty]
time 23133ms: Process A0 switching out of CPU; blocking on I/O until time 23194ms [Q empty]
time 23194ms: Process A0 (tau 2957ms) completed I/O; added to ready queue [Q A0]
time 23196ms: Process A0 (tau 2957ms) started using the CPU for 1700ms burst [Q empty]
time 24896ms: Process A0 (tau 2957ms) completed a CPU burst; 14 bursts to go [Q empty]
time 24896ms: Recalculated tau for process A0: old tau 2957ms ==> new tau 2015ms [Q empty]
time 24896ms: Process A0 switching out of CPU; blocking on I/O until time 25007ms [Q empty]
time 25007ms: Process A0 (tau 2015ms) completed I/O; added to ready queue [Q A0]
time 25009ms: Process A0 (tau 2015ms) started using the CPU for 664ms burst [Q empty]
time 25470ms: Process A2 (tau 108ms) completed I/O; added to ready queue [Q A2]
time 25673ms: Process A0 (tau 2015ms) completed a CPU burst; 13 bursts to go [Q A2]
time 25673ms: Recalculated tau for process A0: old tau 2015ms ==> new tau 1002ms [Q A2]
time 25673ms: Process A0 switching out of CPU; blocking on I/O until time 26007ms [Q A2]
time 25677ms: Process A2 (tau 108ms) started using the CPU for 69ms burst [Q empty]
time 25746ms: Process A2 (tau 108ms) completed a CPU burst; 8 bursts to go [Q empty]
time 25746ms: Recalculated tau for process A2: old tau 108ms ==> new tau 79ms [Q empty]
time 25746ms: Process A2 switching out of CPU; blocking on I/O until time 30092ms [Q empty]
time 26007ms: Process A0 (tau 1002ms) completed I/O; added to ready queue [Q A0]
time 26009ms: Process A0 (tau 1002ms) started using the CPU for 916ms burst [Q empty]
time 26925ms: Process A0 (tau 1002ms) completed a CPU burst; 12 bursts to go [Q empty]
time 26925ms: Recalculated tau for process A0: old tau 1002ms ==> new tau 938ms [Q empty]
time 26925ms: Process A0 switching out of CPU; blocking on I/O until time 27845ms [Q empty]
time 27845ms: Process A0 (tau 938ms) completed I/O; added to ready queue [Q A0]
time 27847ms: Process A0 (tau 938ms) started using the CPU for 1988ms burst [Q empty]
time 29835ms: Process A0 (tau 938ms) completed a CPU burst; 11 bursts to go [Q empty]
time 29835ms: Recalculated tau for process A0: old tau 938ms ==> new tau 1726ms [Q empty]
time 29835ms: Process A0 switching out of CPU; blocking on I/O until time 30604ms [Q empty]
time 30092ms: Process A2 (tau 79ms) completed I/O; added to ready queue [Q A2]
time 30094ms: Process A2 (tau 79ms) started using the CPU for 232ms burst [Q empty]
time 30326ms: Process A2 (tau 79ms) completed a CPU burst; 7 bursts to go [Q empty]
time 30326ms: Recalculated tau for process A2: old tau 79ms ==> new tau 194ms [Q empty]
time 30326ms: Process A2 switching out of CPU; blocking on I/O until time 35448ms [Q empty]
time 30604ms: Process A0 (tau 1726ms) completed I/O; added to ready queue [Q A0]
time 30606ms: Process A0 (tau 1726ms) started using the CPU for 3948ms burst [Q empty]
time 34554ms: Process A0 (tau 1726ms) completed a CPU burst; 10 bursts to go [Q empty]
time 34554ms: Recalculated tau for process A0: old tau 1726ms ==> new tau 3393ms [Q empty]
time 34554ms: Process A0 switching out of CPU; blocking on I/O until time 34977ms [Q empty]
time 34977ms: Process A0 (tau 3393ms) completed I/O; added to ready queue [Q A0]
time 34979ms: Process A0 (tau 3393ms) started using the CPU for 340ms burst [Q empty]
time 35319ms: Process A0 (tau 3393ms) completed a CPU burst; 9 bursts to go [Q empty]
time 35319ms: Recalculated tau for process A0: old tau 3393ms ==> new tau 1104ms [Q empty]
time 35319ms: Process A0 switching out of CPU; blocking on I/O until time 36082ms [Q empty]
time 35448ms: Process A2 (tau 194ms) completed I/O; added to ready queue [Q A2]
time 35450ms: Process A2 (tau 194ms) started using the CPU for 225ms burst [Q empty]
time 35675ms: Process A2 (tau 194ms) completed a CPU burst; 6 bursts to go [Q empty]
time 35675ms: Recalculated tau for process A2: old tau 194ms ==> new tau 218ms [Q empty]
time 35675ms: Process A2 switching out of CPU; blocking on I/O until time 40365ms [Q empty]
time 36082ms: Process A0 (tau 1104ms) completed I/O; added to ready queue [Q A0]
time 36084ms: Process A0 (tau 1104ms) started using the CPU for 2768ms burst [Q empty]
time 38852ms: Process A0 (tau 1104ms) completed a CPU burst; 8 bursts to go [Q empty]
time 38852ms: Recalculated tau for process A0: old tau 1104ms ==> new tau 2352ms [Q empty]
time 38852ms: Process A0 switching out of CPU; blocking on I/O until time 39124ms [Q empty]
time 39124ms: Process A0 (tau 2352ms) completed I/O; added to ready queue [Q A0]
time 39126ms: Process A0 (tau 2352ms) started using the CPU for 1540ms burst [Q empty]
time 40365ms: Process A2 (tau 218ms) completed I/O; added to ready queue [Q A2]
time 40666ms: Process A0 (tau 2352ms) completed a CPU burst; 7 bursts to go [Q A2]
time 40666ms: Recalculated tau for process A0: old tau 2352ms ==> new tau 1743ms [Q A2]
time 40666ms: Process A0 switching out of CPU; blocking on I/O until time 40817ms [Q A2]
time 40670ms: Process A2 (tau 218ms) started using the CPU for 42ms burst [Q empty]
time 40712ms: Process A2 (tau 218ms) completed a CPU burst; 5 bursts to go [Q empty]
time 40712ms: Recalculated tau for process A2: old tau 218ms ==> new tau 86ms [Q empty]
time 40712ms: Process A2 switching out of CPU; blocking on I/O until time 48218ms [Q empty]
time 40817ms: Process A0 (tau 1743ms) completed I/O; added to ready queue [Q A0]
time 40819ms: Process A0 (tau 1743ms) started using the CPU for 1552ms burst [Q empty]
time 42371ms: Process A0 (tau 1743ms) completed a CPU burst; 6 bursts to go [Q empty]
time 42371ms: Recalculated tau for process A0: old tau 1743ms ==> new tau 1600ms [Q empty]
time 42371ms: Process A0 switching out of CPU; blocking on I/O until time 42457ms [Q empty]
time 42457ms: Process A0 (tau 1600ms) completed I/O; added to ready queue [Q A0]
time 42459ms: Process A0 (tau 1600ms) started using the CPU for 224ms burst [Q empty]
time 42683ms: Process A0 (tau 1600ms) completed a CPU burst; 5 bursts to go [Q empty]
time 42683ms: Recalculated tau for process A0: old tau 1600ms ==> new tau 568ms [Q empty]
time 42683ms: Process A0 switching out of CPU; blocking on I/O until time 43335ms [Q empty]
time 43335ms: Process A0 (tau 568ms) completed I/O; added to ready queue [Q A0]
time 43337ms: Process A0 (tau 568ms) started using the CPU for 52ms burst [Q empty]
time 43389ms: Process A0 (tau 568ms) completed a CPU burst; 4 bursts to go [Q empty]
time 43389ms: Recalculated tau for process A0: old tau 568ms ==> new tau 181ms [Q empty]
time 43389ms: Process A0 switching out of CPU; blocking on I/O until time 43469ms [Q empty]
time 43469ms: Process A0 (tau 181ms) completed I/O; added to ready queue [Q A0]
time 43471ms: Process A0 (tau 181ms) started using the CPU for 3548ms burst [Q empty]
time 47019ms: Process A0 (tau 181ms) completed a CPU burst; 3 bursts to go [Q empty]
time 47019ms: Recalculated tau for process A0: old tau 181ms ==> new tau 2707ms [Q empty]
time 47019ms: Process A0 switching out of CPU; blocking on I/O until time 47162ms [Q empty]
time 47162ms: Process A0 (tau 2707ms) completed I/O; added to ready queue [Q A0]
time 47164ms: Process A0 (tau 2707ms) started using the CPU for 820ms burst [Q empty]
time 47984ms: Process A0 (tau 2707ms) completed a CPU burst; 2 bursts to go [Q empty]
time 47984ms: Recalculated tau for process A0: old tau 2707ms ==> new tau 1292ms [Q empty]
time 47984ms: Process A0 switching out of CPU; blocking on I/O until time 48991ms [Q empty]
time 48218ms: Process A2 (tau 86ms) completed I/O; added to ready queue [Q A2]
time 48220ms: Process A2 (tau 86ms) started using the CPU for 335ms burst [Q empty]
time 48555ms: Process A2 (tau 86ms) completed a CPU burst; 4 bursts to go [Q empty]
time 48555ms: Recalculated tau for process A2: old tau 86ms ==> new tau 273ms [Q empty]
time 48555ms: Process A2 switching out of CPU; blocking on I/O until time 53549ms [Q empty]
time 48991ms: Process A0 (tau 1292ms) completed I/O; added to ready queue [Q A0]
time 48993ms: Process A0 (tau 1292ms) started using the CPU for 920ms burst [Q empty]
time 49913ms: Process A0 (tau 1292ms) completed a CPU burst; 1 bursts to go [Q empty]
time 49913ms: Recalculated tau for process A0: old tau 1292ms ==> new tau 1013ms [Q empty]
time 49913ms: Process A0 switching out of CPU; blocking on I/O until time 50363ms [Q empty]
time 50363ms: Process A0 (tau 1013ms) completed I/O; added to ready queue [Q A0]
time 50365ms: Process A0 (tau 1013ms) started using the CPU for 1876ms burst [Q empty]
time 52241ms: Process A0 terminated [Q empty]
time 53549ms: Process A2 (tau 273ms) completed I/O; added to ready queue [Q A2]
time 53551ms: Process A2 (tau 273ms) started using the CPU for 247ms burst [Q empty]
time 53798ms: Process A2 (tau 273ms) completed a CPU burst; 3 bursts to go [Q empty]
time 53798ms: Recalculated tau for process A2: old tau 273ms ==> new tau 254ms [Q empty]
time 53798ms: Process A2 switching out of CPU; blocking on I/O until time 59760ms [Q empty]
time 59760ms: Process A2 (tau 254ms) completed I/O; added to ready queue [Q A2]
time 59762ms: Process A2 (tau 254ms) started using the CPU for 66ms burst [Q empty]
time 59828ms: Process A2 (tau 254ms) completed a CPU burst; 2 bursts to go [Q empty]
time 59828ms: Recalculated tau for process A2: old tau 254ms ==> new tau 113ms [Q empty]
time 59828ms: Process A2 switching out of CPU; blocking on I/O until time 59894ms [Q empty]
time 59894ms: Process A2 (tau 113ms) completed I/O; added to ready queue [Q A2]
time 59896ms: Process A2 (tau 113ms) started using the CPU for 155ms burst [Q empty]
time 60051ms: Process A2 (tau 113ms) completed a CPU burst; 1 bursts to go [Q empty]
time 60051ms: Recalculated tau for process A2: old tau 113ms ==> new tau 145ms [Q empty]
time 60051ms: Process A2 switching out of CPU; blocking on I/O until time 65813ms [Q empty]
time 65813ms: Process A2 (tau 145ms) completed I/O; added to ready queue [Q A2]
time 65815ms: Process A2 (tau 145ms) started using the CPU for 280ms burst [Q empty]
time 66095ms: Process A2 terminated [Q empty]
time 66097ms: Simulator ended for SJF [Q empty]

time 0ms: Simulator started for RR [Q empty]
time 319ms: Process A0 arrived; added to ready queue [Q A0]
time 321ms: Process A0 started using the CPU for 1448ms burst [Q empty]
time 506ms: Process A1 arrived; added to ready queue [Q A1]
time 577ms: Time slice expired; preempting process A0 with 1192ms remaining [Q A1]
time 581ms: Process A1 started using the CPU for 971ms burst [Q A0]
time 821ms: Process A2 arrived; added to ready queue [Q A0 A2]
time 837ms: Time slice expired; preempting process A1 with 715ms remaining [Q A0 A2]
time 841ms: Process A0 started using the CPU for remaining 1192ms of 1448ms burst [Q A2 A1]
time 1097ms: Time slice expired; preempting process A0 with 936ms remaining [Q A2 A1]
time 1101ms: Process A2 started using the CPU for 408ms burst [Q A1 A0]
time 1357ms: Time slice expired; preempting process A2 with 152ms remaining [Q A1 A0]
time 1361ms: Process A1 started using the CPU for remaining 715ms of 971ms burst [Q A0 A2]
time 1617ms: Time slice expired; preempting process A1 with 459ms remaining [Q A0 A2]
time 1621ms: Process A0 started using the CPU for remaining 936ms of 1448ms burst [Q A2 A1]
time 1877ms: Time slice expired; preempting process A0 with 680ms remaining [Q A2 A1]
time 1881ms: Process A2 started using the CPU for remaining 152ms of 408ms burst [Q A1 A0]
time 2033ms: Process A2 completed a CPU burst; 14 bursts to go [Q A1 A0]
time 2033ms: Process A2 switching out of CPU; blocking on I/O until time 7547ms [Q A1 A0]
time 2037ms: Process A1 started using the CPU for remaining 459ms of 971ms burst [Q A0]
time 2293ms: Time slice expired; preempting process A1 with 203ms remaining [Q A0]
time 2297ms: Process A0 started using the CPU for remaining 680ms of 1448ms burst [Q A1]
time 2553ms: Time slice expired; preempting process A0 with 424ms remaining [Q A1]
time 2557ms: Process A1 started using the CPU for remaining 203ms of 971ms burst [Q A0]
time 2760ms: Process A1 completed a CPU burst; 4 bursts to go [Q A0]
time 2760ms: Process A1 switching out of CPU; blocking on I/O until time 3194ms [Q A0]
time 2764ms: Process A0 started using the CPU for remaining 424ms of 1448ms burst [Q empty]
time 3020ms: Time slice expired; no preemption because ready queue is empty [Q empty]
time 3188ms: Process A0 completed a CPU burst; 24 bursts to go [Q empty]
time 3188ms: Process A0 switching out of CPU; blocking on I/O until time 3798ms [Q empty]
time 3194ms: Process A1 completed I/O; added to ready queue [Q A1]
time 3196ms: Process A1 started using the CPU for 129ms burst [Q empty]
time 3325ms: Process A1 completed a CPU burst; 3 bursts to go [Q empty]
time 3325ms: Process A1 switching out of CPU; blocking on I/O until time 4591ms [Q empty]
time 3798ms: Process A0 completed I/O; added to ready queue [Q A0]
time 3800ms: Process A0 started using the CPU for 316ms burst [Q empty]
time 4056ms: Time slice expired; no preemption because ready queue is empty [Q empty]
time 4116ms: Process A0 completed a CPU burst; 23 bursts to go [Q empty]
time 4116ms: Process A0 switching out of CPU; blocking on I/O until time 4592ms [Q empty]
time 4591ms: Process A1 completed I/O; added to ready queue [Q A1]
time 4593ms: Process A1 started using the CPU for 188ms burst [Q empty]
time 4592ms: Process A0 completed I/O; added to ready queue [Q A0]
time 4781ms: Process A1 completed a CPU burst; 2 bursts to go [Q A0]
time 4781ms: Process A1 switching out of CPU; blocking on I/O until time 6279ms [Q A0]
time 4785ms: Process A0 started using the CPU for 3556ms burst [Q empty]
time 5041ms: Time slice expired; no preemption because ready queue is empty [Q empty]
time 5297ms: Time slice expired; no preemption because ready queue is empty [Q empty]
time 5553ms: Time slice expired; no preemption because ready queue is empty [Q empty]
time 5809ms: Time slice expired; no preemption because ready queue is empty [Q empty]
time 6065ms: Time slice expired; no preemption because ready queue is empty [Q empty]
time 6279ms: Process A1 completed I/O; added to ready queue [Q A1]
time 6321ms: Time slice expired; preempting process A0 with 2020ms remaining [Q A1]
time 6325ms: Process A1 started using the CPU for 302ms burst [Q A0]
time 6581ms: Time slice expired; preempting process A1 with 46ms remaining [Q A0]
time 6585ms: Process A0 started using the CPU for remaining 2020ms of 3556ms burst [Q A1]
time 6841ms: Time slice expired; preempting process A0 with 1764ms remaining [Q A1]
time 6845ms: Process A1 started using the CPU for remaining 46ms of 302ms burst [Q A0]
time 6891ms: Process A1 completed a CPU burst; 1 burst to go [Q A0]
time 6891ms: Process A1 switching out of CPU; blocking on I/O until time 8221ms [Q A0]
time 6895ms: Process A0 started using the CPU for remaining 1764ms of 3556ms burst [Q empty]
time 7151ms: Time slice expired; no preemption because ready queue is empty [Q empty]
time 7407ms: Time slice expired; no preemption because ready queue is empty [Q empty]
time 7547ms: Process A2 completed I/O; added to ready queue [Q A2]
time 7663ms: Time slice expired; preempting process A0 with 996ms remaining [Q A2]
time 7667ms: Process A2 started using the CPU for 182ms burst [Q A0]
time 7849ms: Process A2 completed a CPU burst; 13 bursts to go [Q A0]
time 7849ms: Process A2 switching out of CPU; blocking on I/O until time 11595ms [Q A0]
time 7853ms: Process A0 started using the CPU for remaining 996ms of 3556ms burst [Q empty]
time 8109ms: Time slice expired; no preemption because ready queue is empty [Q empty]
time 8221ms: Process A1 completed I/O; added to ready queue [Q A1]
time 8365ms: Time slice expired; preempting process A0 with 484ms remaining [Q A1]
time 8369ms: Process A1 started using the CPU for 73ms burst [Q A0]
time 8442ms: Process A1 terminated [Q A0]
time 8446ms: Process A0 started using the CPU for remaining 484ms of 3556ms burst [Q empty]
time 8702ms: Time slice expired; no preemption because ready queue is empty [Q empty]
time 8930ms: Process A0 completed a CPU burst; 22 bursts to go [Q empty]
time 8930ms: Process A0 switching out of CPU; blocking on I/O until time 9896ms [Q empty]
time 9896ms: Process A0 completed I/O; added to ready queue [Q A0]
time 9898ms: Process A0 started using the CPU for 2516ms burst [Q empty]
time 54903ms: Process A0 terminated [Q empty]
time 61754ms: Process A2 terminated [Q empty]
time 61756ms: Simulator ended for RR [Q empty]
